[2024-12-02T18:44:27.952+0000] {local_task_job_runner.py:123} INFO - ::group::Pre task execution logs
[2024-12-02T18:44:27.989+0000] {taskinstance.py:2613} INFO - Dependencies all met for dep_context=non-requeueable deps ti=<TaskInstance: kafka_hive_pipeline.consume_from_kafka manual__2024-12-02T18:43:33.512281+00:00 [queued]>
[2024-12-02T18:44:28.012+0000] {taskinstance.py:2613} INFO - Dependencies all met for dep_context=requeueable deps ti=<TaskInstance: kafka_hive_pipeline.consume_from_kafka manual__2024-12-02T18:43:33.512281+00:00 [queued]>
[2024-12-02T18:44:28.013+0000] {taskinstance.py:2866} INFO - Starting attempt 1 of 1
[2024-12-02T18:44:28.084+0000] {taskinstance.py:2889} INFO - Executing <Task(PythonOperator): consume_from_kafka> on 2024-12-02 18:43:33.512281+00:00
[2024-12-02T18:44:28.097+0000] {standard_task_runner.py:104} INFO - Running: ['airflow', 'tasks', 'run', 'kafka_hive_pipeline', 'consume_from_kafka', 'manual__2024-12-02T18:43:33.512281+00:00', '--job-id', '153', '--raw', '--subdir', 'DAGS_FOLDER/gestion_airflow.py', '--cfg-path', '/tmp/tmpmlyf0goa']
[2024-12-02T18:44:28.100+0000] {logging_mixin.py:190} WARNING - /home/airflow/.local/lib/python3.12/site-packages/airflow/task/task_runner/standard_task_runner.py:70 DeprecationWarning: This process (pid=541) is multi-threaded, use of fork() may lead to deadlocks in the child.
[2024-12-02T18:44:28.101+0000] {standard_task_runner.py:105} INFO - Job 153: Subtask consume_from_kafka
[2024-12-02T18:44:28.101+0000] {standard_task_runner.py:72} INFO - Started process 561 to run task
[2024-12-02T18:44:28.225+0000] {task_command.py:467} INFO - Running <TaskInstance: kafka_hive_pipeline.consume_from_kafka manual__2024-12-02T18:43:33.512281+00:00 [running]> on host 45770b1a429e
[2024-12-02T18:44:28.450+0000] {taskinstance.py:3132} INFO - Exporting env vars: AIRFLOW_CTX_DAG_OWNER='airflow' AIRFLOW_CTX_DAG_ID='kafka_hive_pipeline' AIRFLOW_CTX_TASK_ID='consume_from_kafka' AIRFLOW_CTX_EXECUTION_DATE='2024-12-02T18:43:33.512281+00:00' AIRFLOW_CTX_TRY_NUMBER='1' AIRFLOW_CTX_DAG_RUN_ID='manual__2024-12-02T18:43:33.512281+00:00'
[2024-12-02T18:44:28.453+0000] {taskinstance.py:731} INFO - ::endgroup::
[2024-12-02T18:44:28.860+0000] {hive.py:475} INFO - USE `default`
[2024-12-02T18:44:29.238+0000] {hive.py:475} INFO - 
    CREATE TABLE IF NOT EXISTS sales (
        id STRING,
        invoice_id STRING,
        branch STRING,
        city STRING,
        customer_type STRING,
        gender STRING,
        product_line STRING,
        unit_price FLOAT,
        quantity INT,
        tax_5_percent FLOAT,
        total FLOAT,
        `date` STRING,
        time STRING,
        payment STRING,
        cogs FLOAT,
        gross_margin_percentage FLOAT,
        gross_income FLOAT,
        rating FLOAT
    ) STORED AS ORC
    
[2024-12-02T18:44:29.279+0000] {kafka_to_hive_with_redis.py:70} INFO - Subscribed to topic 'topic-batch'
[2024-12-02T18:44:43.380+0000] {local_task_job_runner.py:346} WARNING - State of this instance has been externally set to queued. Terminating instance.
[2024-12-02T18:44:43.382+0000] {local_task_job_runner.py:245} INFO - ::endgroup::
[2024-12-02T18:44:43.384+0000] {process_utils.py:132} INFO - Sending 15 to group 561. PIDs of all processes in the group: [561]
[2024-12-02T18:44:43.385+0000] {process_utils.py:87} INFO - Sending the signal 15 to group 561
[2024-12-02T18:44:44.287+0000] {taskinstance.py:3093} ERROR - Received SIGTERM. Terminating subprocesses.
[2024-12-02T18:44:44.341+0000] {taskinstance.py:3311} ERROR - Task failed with exception
Traceback (most recent call last):
  File "/home/airflow/.local/lib/python3.12/site-packages/airflow/models/taskinstance.py", line 767, in _execute_task
    result = _execute_callable(context=context, **execute_callable_kwargs)
             ^^^^^^^^^^^^^^^^^^^^^^^^^^^^^^^^^^^^^^^^^^^^^^^^^^^^^^^^^^^^^
  File "/home/airflow/.local/lib/python3.12/site-packages/airflow/models/taskinstance.py", line 733, in _execute_callable
    return ExecutionCallableRunner(
           ^^^^^^^^^^^^^^^^^^^^^^^^
  File "/home/airflow/.local/lib/python3.12/site-packages/airflow/utils/operator_helpers.py", line 252, in run
    return self.func(*args, **kwargs)
           ^^^^^^^^^^^^^^^^^^^^^^^^^^
  File "/home/airflow/.local/lib/python3.12/site-packages/airflow/models/baseoperator.py", line 417, in wrapper
    return func(self, *args, **kwargs)
           ^^^^^^^^^^^^^^^^^^^^^^^^^^^
  File "/home/airflow/.local/lib/python3.12/site-packages/airflow/operators/python.py", line 238, in execute
    return_value = self.execute_callable()
                   ^^^^^^^^^^^^^^^^^^^^^^^
  File "/home/airflow/.local/lib/python3.12/site-packages/airflow/operators/python.py", line 256, in execute_callable
    return runner.run(*self.op_args, **self.op_kwargs)
           ^^^^^^^^^^^^^^^^^^^^^^^^^^^^^^^^^^^^^^^^^^^
  File "/home/airflow/.local/lib/python3.12/site-packages/airflow/utils/operator_helpers.py", line 252, in run
    return self.func(*args, **kwargs)
           ^^^^^^^^^^^^^^^^^^^^^^^^^^
  File "/opt/airflow/dags/kafka_to_hive_with_redis.py", line 82, in consume_kafka_to_hive_with_redis
    msg = consumer.poll(timeout=5.0)
          ^^^^^^^^^^^^^^^^^^^^^^^^^^
  File "/home/airflow/.local/lib/python3.12/site-packages/airflow/models/taskinstance.py", line 3095, in signal_handler
    raise AirflowTaskTerminated("Task received SIGTERM signal")
airflow.exceptions.AirflowTaskTerminated: Task received SIGTERM signal
[2024-12-02T18:44:44.364+0000] {taskinstance.py:1225} INFO - Marking task as FAILED. dag_id=kafka_hive_pipeline, task_id=consume_from_kafka, run_id=manual__2024-12-02T18:43:33.512281+00:00, execution_date=20241202T184333, start_date=20241202T184443, end_date=20241202T184444
[2024-12-02T18:44:44.458+0000] {taskinstance.py:340} INFO - ::group::Post task execution logs
[2024-12-02T18:44:44.497+0000] {process_utils.py:80} INFO - Process psutil.Process(pid=561, status='terminated', exitcode=2, started='18:44:27') (561) terminated with exit code 2
