[2024-12-06T16:04:16.018+0000] {local_task_job_runner.py:123} INFO - ::group::Pre task execution logs
[2024-12-06T16:04:16.066+0000] {taskinstance.py:2613} INFO - Dependencies all met for dep_context=non-requeueable deps ti=<TaskInstance: kafka_hive_pipeline_threaded.sync_producer_and_consumer manual__2024-12-04T10:55:18.453222+00:00 [queued]>
[2024-12-06T16:04:16.099+0000] {taskinstance.py:2613} INFO - Dependencies all met for dep_context=requeueable deps ti=<TaskInstance: kafka_hive_pipeline_threaded.sync_producer_and_consumer manual__2024-12-04T10:55:18.453222+00:00 [queued]>
[2024-12-06T16:04:16.101+0000] {taskinstance.py:2866} INFO - Starting attempt 3 of 1
[2024-12-06T16:04:16.201+0000] {taskinstance.py:2889} INFO - Executing <Task(PythonOperator): sync_producer_and_consumer> on 2024-12-04 10:55:18.453222+00:00
[2024-12-06T16:04:16.227+0000] {standard_task_runner.py:104} INFO - Running: ['airflow', 'tasks', 'run', 'kafka_hive_pipeline_threaded', 'sync_producer_and_consumer', 'manual__2024-12-04T10:55:18.453222+00:00', '--job-id', '211', '--raw', '--subdir', 'DAGS_FOLDER/gestion_airflow.py', '--cfg-path', '/tmp/tmpv9fa6w1n']
[2024-12-06T16:04:16.232+0000] {logging_mixin.py:190} WARNING - /home/airflow/.local/lib/python3.12/site-packages/airflow/task/task_runner/standard_task_runner.py:70 DeprecationWarning: This process (pid=69) is multi-threaded, use of fork() may lead to deadlocks in the child.
[2024-12-06T16:04:16.235+0000] {standard_task_runner.py:105} INFO - Job 211: Subtask sync_producer_and_consumer
[2024-12-06T16:04:16.235+0000] {standard_task_runner.py:72} INFO - Started process 96 to run task
[2024-12-06T16:04:16.475+0000] {task_command.py:467} INFO - Running <TaskInstance: kafka_hive_pipeline_threaded.sync_producer_and_consumer manual__2024-12-04T10:55:18.453222+00:00 [running]> on host 45770b1a429e
[2024-12-06T16:04:16.889+0000] {taskinstance.py:3132} INFO - Exporting env vars: AIRFLOW_CTX_DAG_OWNER='airflow' AIRFLOW_CTX_DAG_ID='kafka_hive_pipeline_threaded' AIRFLOW_CTX_TASK_ID='sync_producer_and_consumer' AIRFLOW_CTX_EXECUTION_DATE='2024-12-04T10:55:18.453222+00:00' AIRFLOW_CTX_TRY_NUMBER='3' AIRFLOW_CTX_DAG_RUN_ID='manual__2024-12-04T10:55:18.453222+00:00'
[2024-12-06T16:04:16.892+0000] {taskinstance.py:731} INFO - ::endgroup::
[2024-12-06T16:04:16.999+0000] {TSocket.py:149} INFO - Could not connect to ('192.168.0.7', 10000)
Traceback (most recent call last):
  File "/home/airflow/.local/lib/python3.12/site-packages/thrift/transport/TSocket.py", line 144, in open
    handle.connect(sockaddr)
ConnectionRefusedError: [Errno 111] Connection refused
[2024-12-06T16:04:17.004+0000] {TSocket.py:152} ERROR - Could not connect to any of [('192.168.0.7', 10000)]
[2024-12-06T16:04:17.005+0000] {logging_mixin.py:190} WARNING - Exception in thread Thread-2 (consume_kafka_to_hive_with_redis):
[2024-12-06T16:04:17.006+0000] {logging_mixin.py:190} WARNING - Traceback (most recent call last):
[2024-12-06T16:04:17.007+0000] {logging_mixin.py:190} WARNING -   File "/usr/local/lib/python3.12/threading.py", line 1075, in _bootstrap_inner
[2024-12-06T16:04:17.009+0000] {logging_mixin.py:190} WARNING -     self.run()
[2024-12-06T16:04:17.011+0000] {logging_mixin.py:190} WARNING -   File "/usr/local/lib/python3.12/threading.py", line 1012, in run
[2024-12-06T16:04:17.012+0000] {logging_mixin.py:190} WARNING -     self._target(*self._args, **self._kwargs)
[2024-12-06T16:04:17.014+0000] {logging_mixin.py:190} WARNING -   File "/opt/airflow/dags/kafka_to_hive_with_redis.py", line 35, in consume_kafka_to_hive_with_redis
[2024-12-06T16:04:17.021+0000] {logging_mixin.py:190} WARNING -     conn = hive.Connection(host='hive-server', port=10000, username='hive', database='default')
[2024-12-06T16:04:17.023+0000] {logging_mixin.py:190} WARNING -            ^^^^^^^^^^^^^^^^^^^^^^^^^^^^^^^^^^^^^^^^^^^^^^^^^^^^^^^^^^^^^^^^^^^^^^^^^^^^^^^^^^^^
[2024-12-06T16:04:17.024+0000] {logging_mixin.py:190} WARNING -   File "/home/airflow/.local/lib/python3.12/site-packages/pyhive/hive.py", line 269, in __init__
[2024-12-06T16:04:17.028+0000] {logging_mixin.py:190} WARNING -     self._transport.open()
[2024-12-06T16:04:17.030+0000] {logging_mixin.py:190} WARNING -   File "/home/airflow/.local/lib/python3.12/site-packages/thrift_sasl/__init__.py", line 74, in open
[2024-12-06T16:04:17.031+0000] {logging_mixin.py:190} WARNING -     self._trans.open()
[2024-12-06T16:04:17.033+0000] {logging_mixin.py:190} WARNING -   File "/home/airflow/.local/lib/python3.12/site-packages/thrift/transport/TSocket.py", line 153, in open
[2024-12-06T16:04:17.037+0000] {logging_mixin.py:190} WARNING -     raise TTransportException(type=TTransportException.NOT_OPEN, message=msg)
[2024-12-06T16:04:17.040+0000] {logging_mixin.py:190} WARNING - thrift.transport.TTransport.TTransportException: Could not connect to any of [('192.168.0.7', 10000)]
[2024-12-06T16:04:17.130+0000] {csv_to_kafka_with_redis.py:50} INFO - Loaded CSV Data:
    Invoice ID Branch       City  ... gross margin percentage gross income Rating
0  750-67-8428      A     Yangon  ...                4.761905      26.1415    9.1
1  226-31-3081      C  Naypyitaw  ...                4.761905       3.8200    9.6
2  631-41-3108      A     Yangon  ...                4.761905      16.2155    7.4
3  123-19-1176      A     Yangon  ...                4.761905      23.2880    8.4
4  373-73-7910      A     Yangon  ...                4.761905      30.2085    5.3

[5 rows x 17 columns]
[2024-12-06T16:04:17.136+0000] {csv_to_kafka_with_redis.py:84} INFO - Row data before serialization: {'id': '4947cda6-8a92-4b80-b7ab-956711378053', 'invoice_id': '750-67-8428', 'branch': 'A', 'city': 'Yangon', 'customer_type': 'Member', 'gender': 'Female', 'product_line': 'Health and beauty', 'unit_price': 74.69, 'quantity': 7, 'tax_5_percent': 26.1415, 'total': 548.9715, 'date': '1/5/2019', 'time': '13:08', 'payment': 'Ewallet', 'cogs': 522.83, 'gross_margin_percentage': 4.761904762, 'gross_income': 26.1415, 'rating': 9.1}
[2024-12-06T16:04:25.149+0000] {csv_to_kafka_with_redis.py:90} ERROR - Error producing message: KafkaError{code=_VALUE_SERIALIZATION,val=-161,str="HTTPConnectionPool(host='schema-registry', port=8081): Max retries exceeded with url: /subjects/batch-topic-value/versions?normalize=False (Caused by NameResolutionError("<urllib3.connection.HTTPConnection object at 0x7fae6fc52f90>: Failed to resolve 'schema-registry' ([Errno -3] Temporary failure in name resolution)"))"}
[2024-12-06T16:04:25.151+0000] {csv_to_kafka_with_redis.py:84} INFO - Row data before serialization: {'id': '9b8f81cd-82ff-454f-8f40-973038981ad9', 'invoice_id': '226-31-3081', 'branch': 'C', 'city': 'Naypyitaw', 'customer_type': 'Normal', 'gender': 'Female', 'product_line': 'Electronic accessories', 'unit_price': 15.28, 'quantity': 5, 'tax_5_percent': 3.82, 'total': 80.22, 'date': '3/8/2019', 'time': '10:29', 'payment': 'Cash', 'cogs': 76.4, 'gross_margin_percentage': 4.761904762, 'gross_income': 3.82, 'rating': 9.6}
[2024-12-06T16:04:28.463+0000] {csv_to_kafka_with_redis.py:90} ERROR - Error producing message: KafkaError{code=_VALUE_SERIALIZATION,val=-161,str="HTTPConnectionPool(host='schema-registry', port=8081): Max retries exceeded with url: /subjects/batch-topic-value/versions?normalize=False (Caused by NameResolutionError("<urllib3.connection.HTTPConnection object at 0x7fae967b6390>: Failed to resolve 'schema-registry' ([Errno -2] Name or service not known)"))"}
[2024-12-06T16:04:28.466+0000] {csv_to_kafka_with_redis.py:84} INFO - Row data before serialization: {'id': '0cfd1add-811e-45ac-8bdf-1fcad2855818', 'invoice_id': '631-41-3108', 'branch': 'A', 'city': 'Yangon', 'customer_type': 'Normal', 'gender': 'Male', 'product_line': 'Home and lifestyle', 'unit_price': 46.33, 'quantity': 7, 'tax_5_percent': 16.2155, 'total': 340.5255, 'date': '3/3/2019', 'time': '13:23', 'payment': 'Credit card', 'cogs': 324.31, 'gross_margin_percentage': 4.761904762, 'gross_income': 16.2155, 'rating': 7.4}
[2024-12-06T16:04:28.470+0000] {csv_to_kafka_with_redis.py:90} ERROR - Error producing message: KafkaError{code=_VALUE_SERIALIZATION,val=-161,str="HTTPConnectionPool(host='schema-registry', port=8081): Max retries exceeded with url: /subjects/batch-topic-value/versions?normalize=False (Caused by NewConnectionError('<urllib3.connection.HTTPConnection object at 0x7fae96788110>: Failed to establish a new connection: [Errno 111] Connection refused'))"}
[2024-12-06T16:04:28.471+0000] {csv_to_kafka_with_redis.py:84} INFO - Row data before serialization: {'id': '50320d05-bdae-455e-8da1-36aa2dbbd71d', 'invoice_id': '123-19-1176', 'branch': 'A', 'city': 'Yangon', 'customer_type': 'Member', 'gender': 'Male', 'product_line': 'Health and beauty', 'unit_price': 58.22, 'quantity': 8, 'tax_5_percent': 23.288, 'total': 489.048, 'date': '1/27/2019', 'time': '20:33', 'payment': 'Ewallet', 'cogs': 465.76, 'gross_margin_percentage': 4.761904762, 'gross_income': 23.288, 'rating': 8.4}
[2024-12-06T16:04:28.476+0000] {csv_to_kafka_with_redis.py:90} ERROR - Error producing message: KafkaError{code=_VALUE_SERIALIZATION,val=-161,str="HTTPConnectionPool(host='schema-registry', port=8081): Max retries exceeded with url: /subjects/batch-topic-value/versions?normalize=False (Caused by NewConnectionError('<urllib3.connection.HTTPConnection object at 0x7fae9678aa20>: Failed to establish a new connection: [Errno 111] Connection refused'))"}
[2024-12-06T16:04:28.477+0000] {csv_to_kafka_with_redis.py:84} INFO - Row data before serialization: {'id': '1363edd6-3647-4aa9-8515-6600b62d3d49', 'invoice_id': '373-73-7910', 'branch': 'A', 'city': 'Yangon', 'customer_type': 'Normal', 'gender': 'Male', 'product_line': 'Sports and travel', 'unit_price': 86.31, 'quantity': 7, 'tax_5_percent': 30.2085, 'total': 634.3785, 'date': '2/8/2019', 'time': '10:37', 'payment': 'Ewallet', 'cogs': 604.17, 'gross_margin_percentage': 4.761904762, 'gross_income': 30.2085, 'rating': 5.3}
[2024-12-06T16:04:28.481+0000] {csv_to_kafka_with_redis.py:90} ERROR - Error producing message: KafkaError{code=_VALUE_SERIALIZATION,val=-161,str="HTTPConnectionPool(host='schema-registry', port=8081): Max retries exceeded with url: /subjects/batch-topic-value/versions?normalize=False (Caused by NewConnectionError('<urllib3.connection.HTTPConnection object at 0x7fae9675f4a0>: Failed to establish a new connection: [Errno 111] Connection refused'))"}
[2024-12-06T16:04:28.483+0000] {csv_to_kafka_with_redis.py:84} INFO - Row data before serialization: {'id': 'd90b7049-f4e8-41c7-89c1-c1fc9c8e5506', 'invoice_id': '699-14-3026', 'branch': 'C', 'city': 'Naypyitaw', 'customer_type': 'Normal', 'gender': 'Male', 'product_line': 'Electronic accessories', 'unit_price': 85.39, 'quantity': 7, 'tax_5_percent': 29.8865, 'total': 627.6165, 'date': '3/25/2019', 'time': '18:30', 'payment': 'Ewallet', 'cogs': 597.73, 'gross_margin_percentage': 4.761904762, 'gross_income': 29.8865, 'rating': 4.1}
[2024-12-06T16:04:28.487+0000] {csv_to_kafka_with_redis.py:90} ERROR - Error producing message: KafkaError{code=_VALUE_SERIALIZATION,val=-161,str="HTTPConnectionPool(host='schema-registry', port=8081): Max retries exceeded with url: /subjects/batch-topic-value/versions?normalize=False (Caused by NewConnectionError('<urllib3.connection.HTTPConnection object at 0x7fae9675f590>: Failed to establish a new connection: [Errno 111] Connection refused'))"}
[2024-12-06T16:04:28.488+0000] {csv_to_kafka_with_redis.py:84} INFO - Row data before serialization: {'id': '12573fca-72cb-4023-ac05-a8b2f0b8814e', 'invoice_id': '355-53-5943', 'branch': 'A', 'city': 'Yangon', 'customer_type': 'Member', 'gender': 'Female', 'product_line': 'Electronic accessories', 'unit_price': 68.84, 'quantity': 6, 'tax_5_percent': 20.652, 'total': 433.692, 'date': '2/25/2019', 'time': '14:36', 'payment': 'Ewallet', 'cogs': 413.04, 'gross_margin_percentage': 4.761904762, 'gross_income': 20.652, 'rating': 5.8}
[2024-12-06T16:04:28.493+0000] {csv_to_kafka_with_redis.py:90} ERROR - Error producing message: KafkaError{code=_VALUE_SERIALIZATION,val=-161,str="HTTPConnectionPool(host='schema-registry', port=8081): Max retries exceeded with url: /subjects/batch-topic-value/versions?normalize=False (Caused by NewConnectionError('<urllib3.connection.HTTPConnection object at 0x7fae967b5880>: Failed to establish a new connection: [Errno 111] Connection refused'))"}
[2024-12-06T16:04:28.497+0000] {csv_to_kafka_with_redis.py:84} INFO - Row data before serialization: {'id': '533a66e3-8c42-4303-a5c3-d5229dfa72ce', 'invoice_id': '315-22-5665', 'branch': 'C', 'city': 'Naypyitaw', 'customer_type': 'Normal', 'gender': 'Female', 'product_line': 'Home and lifestyle', 'unit_price': 73.56, 'quantity': 10, 'tax_5_percent': 36.78, 'total': 772.38, 'date': '2/24/2019', 'time': '11:38', 'payment': 'Ewallet', 'cogs': 735.6, 'gross_margin_percentage': 4.761904762, 'gross_income': 36.78, 'rating': 8.0}
[2024-12-06T16:04:28.502+0000] {csv_to_kafka_with_redis.py:90} ERROR - Error producing message: KafkaError{code=_VALUE_SERIALIZATION,val=-161,str="HTTPConnectionPool(host='schema-registry', port=8081): Max retries exceeded with url: /subjects/batch-topic-value/versions?normalize=False (Caused by NewConnectionError('<urllib3.connection.HTTPConnection object at 0x7fae967b5370>: Failed to establish a new connection: [Errno 111] Connection refused'))"}
[2024-12-06T16:04:28.504+0000] {csv_to_kafka_with_redis.py:84} INFO - Row data before serialization: {'id': 'a9861317-4920-4606-812a-9b086f7b8f74', 'invoice_id': '665-32-9167', 'branch': 'A', 'city': 'Yangon', 'customer_type': 'Member', 'gender': 'Female', 'product_line': 'Health and beauty', 'unit_price': 36.26, 'quantity': 2, 'tax_5_percent': 3.626, 'total': 76.146, 'date': '1/10/2019', 'time': '17:15', 'payment': 'Credit card', 'cogs': 72.52, 'gross_margin_percentage': 4.761904762, 'gross_income': 3.626, 'rating': 7.2}
[2024-12-06T16:04:28.508+0000] {csv_to_kafka_with_redis.py:90} ERROR - Error producing message: KafkaError{code=_VALUE_SERIALIZATION,val=-161,str="HTTPConnectionPool(host='schema-registry', port=8081): Max retries exceeded with url: /subjects/batch-topic-value/versions?normalize=False (Caused by NewConnectionError('<urllib3.connection.HTTPConnection object at 0x7fae967b6a50>: Failed to establish a new connection: [Errno 111] Connection refused'))"}
[2024-12-06T16:04:28.510+0000] {csv_to_kafka_with_redis.py:84} INFO - Row data before serialization: {'id': 'b7141e68-233b-4c11-ac06-395466187fb9', 'invoice_id': '692-92-5582', 'branch': 'B', 'city': 'Mandalay', 'customer_type': 'Member', 'gender': 'Female', 'product_line': 'Food and beverages', 'unit_price': 54.84, 'quantity': 3, 'tax_5_percent': 8.226, 'total': 172.746, 'date': '2/20/2019', 'time': '13:27', 'payment': 'Credit card', 'cogs': 164.52, 'gross_margin_percentage': 4.761904762, 'gross_income': 8.226, 'rating': 5.9}
[2024-12-06T16:04:28.514+0000] {csv_to_kafka_with_redis.py:90} ERROR - Error producing message: KafkaError{code=_VALUE_SERIALIZATION,val=-161,str="HTTPConnectionPool(host='schema-registry', port=8081): Max retries exceeded with url: /subjects/batch-topic-value/versions?normalize=False (Caused by NewConnectionError('<urllib3.connection.HTTPConnection object at 0x7fae967b6ff0>: Failed to establish a new connection: [Errno 111] Connection refused'))"}
[2024-12-06T16:04:28.517+0000] {csv_to_kafka_with_redis.py:84} INFO - Row data before serialization: {'id': 'e090971d-13be-4a5a-b972-7246782d2de2', 'invoice_id': '351-62-0822', 'branch': 'B', 'city': 'Mandalay', 'customer_type': 'Member', 'gender': 'Female', 'product_line': 'Fashion accessories', 'unit_price': 14.48, 'quantity': 4, 'tax_5_percent': 2.896, 'total': 60.816, 'date': '2/6/2019', 'time': '18:07', 'payment': 'Ewallet', 'cogs': 57.92, 'gross_margin_percentage': 4.761904762, 'gross_income': 2.896, 'rating': 4.5}
[2024-12-06T16:04:28.522+0000] {csv_to_kafka_with_redis.py:90} ERROR - Error producing message: KafkaError{code=_VALUE_SERIALIZATION,val=-161,str="HTTPConnectionPool(host='schema-registry', port=8081): Max retries exceeded with url: /subjects/batch-topic-value/versions?normalize=False (Caused by NewConnectionError('<urllib3.connection.HTTPConnection object at 0x7fae967b7500>: Failed to establish a new connection: [Errno 111] Connection refused'))"}
[2024-12-06T16:04:28.524+0000] {csv_to_kafka_with_redis.py:84} INFO - Row data before serialization: {'id': 'ffd3aaf2-e98d-4eed-9102-4f9756480e76', 'invoice_id': '529-56-3974', 'branch': 'B', 'city': 'Mandalay', 'customer_type': 'Member', 'gender': 'Male', 'product_line': 'Electronic accessories', 'unit_price': 25.51, 'quantity': 4, 'tax_5_percent': 5.102, 'total': 107.142, 'date': '3/9/2019', 'time': '17:03', 'payment': 'Cash', 'cogs': 102.04, 'gross_margin_percentage': 4.761904762, 'gross_income': 5.102, 'rating': 6.8}
[2024-12-06T16:04:28.529+0000] {csv_to_kafka_with_redis.py:90} ERROR - Error producing message: KafkaError{code=_VALUE_SERIALIZATION,val=-161,str="HTTPConnectionPool(host='schema-registry', port=8081): Max retries exceeded with url: /subjects/batch-topic-value/versions?normalize=False (Caused by NewConnectionError('<urllib3.connection.HTTPConnection object at 0x7fae967b7aa0>: Failed to establish a new connection: [Errno 111] Connection refused'))"}
[2024-12-06T16:04:28.531+0000] {csv_to_kafka_with_redis.py:84} INFO - Row data before serialization: {'id': 'eac2fddc-cbab-4c44-b21f-bad3ea862a69', 'invoice_id': '365-64-0515', 'branch': 'A', 'city': 'Yangon', 'customer_type': 'Normal', 'gender': 'Female', 'product_line': 'Electronic accessories', 'unit_price': 46.95, 'quantity': 5, 'tax_5_percent': 11.7375, 'total': 246.4875, 'date': '2/12/2019', 'time': '10:25', 'payment': 'Ewallet', 'cogs': 234.75, 'gross_margin_percentage': 4.761904762, 'gross_income': 11.7375, 'rating': 7.1}
[2024-12-06T16:04:28.536+0000] {csv_to_kafka_with_redis.py:90} ERROR - Error producing message: KafkaError{code=_VALUE_SERIALIZATION,val=-161,str="HTTPConnectionPool(host='schema-registry', port=8081): Max retries exceeded with url: /subjects/batch-topic-value/versions?normalize=False (Caused by NewConnectionError('<urllib3.connection.HTTPConnection object at 0x7fae9675f4d0>: Failed to establish a new connection: [Errno 111] Connection refused'))"}
[2024-12-06T16:04:28.537+0000] {csv_to_kafka_with_redis.py:84} INFO - Row data before serialization: {'id': 'ab3e40df-026e-4cf0-be9b-4ffde359c537', 'invoice_id': '252-56-2699', 'branch': 'A', 'city': 'Yangon', 'customer_type': 'Normal', 'gender': 'Male', 'product_line': 'Food and beverages', 'unit_price': 43.19, 'quantity': 10, 'tax_5_percent': 21.595, 'total': 453.495, 'date': '2/7/2019', 'time': '16:48', 'payment': 'Ewallet', 'cogs': 431.9, 'gross_margin_percentage': 4.761904762, 'gross_income': 21.595, 'rating': 8.2}
[2024-12-06T16:04:28.541+0000] {csv_to_kafka_with_redis.py:90} ERROR - Error producing message: KafkaError{code=_VALUE_SERIALIZATION,val=-161,str="HTTPConnectionPool(host='schema-registry', port=8081): Max retries exceeded with url: /subjects/batch-topic-value/versions?normalize=False (Caused by NewConnectionError('<urllib3.connection.HTTPConnection object at 0x7fae9678b320>: Failed to establish a new connection: [Errno 111] Connection refused'))"}
[2024-12-06T16:04:28.543+0000] {csv_to_kafka_with_redis.py:84} INFO - Row data before serialization: {'id': 'e63aa201-4173-4ba7-b536-e8a98ac6f5e6', 'invoice_id': '829-34-3910', 'branch': 'A', 'city': 'Yangon', 'customer_type': 'Normal', 'gender': 'Female', 'product_line': 'Health and beauty', 'unit_price': 71.38, 'quantity': 10, 'tax_5_percent': 35.69, 'total': 749.49, 'date': '3/29/2019', 'time': '19:21', 'payment': 'Cash', 'cogs': 713.8, 'gross_margin_percentage': 4.761904762, 'gross_income': 35.69, 'rating': 5.7}
[2024-12-06T16:04:28.548+0000] {csv_to_kafka_with_redis.py:90} ERROR - Error producing message: KafkaError{code=_VALUE_SERIALIZATION,val=-161,str="HTTPConnectionPool(host='schema-registry', port=8081): Max retries exceeded with url: /subjects/batch-topic-value/versions?normalize=False (Caused by NewConnectionError('<urllib3.connection.HTTPConnection object at 0x7fae967b71a0>: Failed to establish a new connection: [Errno 111] Connection refused'))"}
[2024-12-06T16:04:28.550+0000] {csv_to_kafka_with_redis.py:84} INFO - Row data before serialization: {'id': '18b326cb-274d-4c6d-8590-4d8b047d7694', 'invoice_id': '299-46-1805', 'branch': 'B', 'city': 'Mandalay', 'customer_type': 'Member', 'gender': 'Female', 'product_line': 'Sports and travel', 'unit_price': 93.72, 'quantity': 6, 'tax_5_percent': 28.116, 'total': 590.436, 'date': '1/15/2019', 'time': '16:19', 'payment': 'Cash', 'cogs': 562.32, 'gross_margin_percentage': 4.761904762, 'gross_income': 28.116, 'rating': 4.5}
[2024-12-06T16:04:28.554+0000] {csv_to_kafka_with_redis.py:90} ERROR - Error producing message: KafkaError{code=_VALUE_SERIALIZATION,val=-161,str="HTTPConnectionPool(host='schema-registry', port=8081): Max retries exceeded with url: /subjects/batch-topic-value/versions?normalize=False (Caused by NewConnectionError('<urllib3.connection.HTTPConnection object at 0x7fae967b6f00>: Failed to establish a new connection: [Errno 111] Connection refused'))"}
[2024-12-06T16:04:28.556+0000] {csv_to_kafka_with_redis.py:84} INFO - Row data before serialization: {'id': 'd6a24278-4d1f-4a20-abc4-4b39c06611bf', 'invoice_id': '656-95-9349', 'branch': 'A', 'city': 'Yangon', 'customer_type': 'Member', 'gender': 'Female', 'product_line': 'Health and beauty', 'unit_price': 68.93, 'quantity': 7, 'tax_5_percent': 24.1255, 'total': 506.6355, 'date': '3/11/2019', 'time': '11:03', 'payment': 'Credit card', 'cogs': 482.51, 'gross_margin_percentage': 4.761904762, 'gross_income': 24.1255, 'rating': 4.6}
[2024-12-06T16:04:28.559+0000] {csv_to_kafka_with_redis.py:90} ERROR - Error producing message: KafkaError{code=_VALUE_SERIALIZATION,val=-161,str="HTTPConnectionPool(host='schema-registry', port=8081): Max retries exceeded with url: /subjects/batch-topic-value/versions?normalize=False (Caused by NewConnectionError('<urllib3.connection.HTTPConnection object at 0x7fae967b6ae0>: Failed to establish a new connection: [Errno 111] Connection refused'))"}
[2024-12-06T16:04:28.561+0000] {csv_to_kafka_with_redis.py:84} INFO - Row data before serialization: {'id': '35eba9b2-882d-4225-8132-c1241054449f', 'invoice_id': '765-26-6951', 'branch': 'A', 'city': 'Yangon', 'customer_type': 'Normal', 'gender': 'Male', 'product_line': 'Sports and travel', 'unit_price': 72.61, 'quantity': 6, 'tax_5_percent': 21.783, 'total': 457.443, 'date': '1/1/2019', 'time': '10:39', 'payment': 'Credit card', 'cogs': 435.66, 'gross_margin_percentage': 4.761904762, 'gross_income': 21.783, 'rating': 6.9}
[2024-12-06T16:04:28.565+0000] {csv_to_kafka_with_redis.py:90} ERROR - Error producing message: KafkaError{code=_VALUE_SERIALIZATION,val=-161,str="HTTPConnectionPool(host='schema-registry', port=8081): Max retries exceeded with url: /subjects/batch-topic-value/versions?normalize=False (Caused by NewConnectionError('<urllib3.connection.HTTPConnection object at 0x7fae967b5370>: Failed to establish a new connection: [Errno 111] Connection refused'))"}
[2024-12-06T16:04:28.567+0000] {csv_to_kafka_with_redis.py:84} INFO - Row data before serialization: {'id': '07590245-c50b-41d3-a875-3fc65defa8f9', 'invoice_id': '329-62-1586', 'branch': 'A', 'city': 'Yangon', 'customer_type': 'Normal', 'gender': 'Male', 'product_line': 'Food and beverages', 'unit_price': 54.67, 'quantity': 3, 'tax_5_percent': 8.2005, 'total': 172.2105, 'date': '1/21/2019', 'time': '18:00', 'payment': 'Credit card', 'cogs': 164.01, 'gross_margin_percentage': 4.761904762, 'gross_income': 8.2005, 'rating': 8.6}
[2024-12-06T16:04:28.572+0000] {csv_to_kafka_with_redis.py:90} ERROR - Error producing message: KafkaError{code=_VALUE_SERIALIZATION,val=-161,str="HTTPConnectionPool(host='schema-registry', port=8081): Max retries exceeded with url: /subjects/batch-topic-value/versions?normalize=False (Caused by NewConnectionError('<urllib3.connection.HTTPConnection object at 0x7fae967b7e00>: Failed to establish a new connection: [Errno 111] Connection refused'))"}
[2024-12-06T16:04:28.574+0000] {csv_to_kafka_with_redis.py:84} INFO - Row data before serialization: {'id': 'ff13ab85-9612-44ba-96bb-bab4b3da96e0', 'invoice_id': '319-50-3348', 'branch': 'B', 'city': 'Mandalay', 'customer_type': 'Normal', 'gender': 'Female', 'product_line': 'Home and lifestyle', 'unit_price': 40.3, 'quantity': 2, 'tax_5_percent': 4.03, 'total': 84.63, 'date': '3/11/2019', 'time': '15:30', 'payment': 'Ewallet', 'cogs': 80.6, 'gross_margin_percentage': 4.761904762, 'gross_income': 4.03, 'rating': 4.4}
[2024-12-06T16:04:28.579+0000] {csv_to_kafka_with_redis.py:90} ERROR - Error producing message: KafkaError{code=_VALUE_SERIALIZATION,val=-161,str="HTTPConnectionPool(host='schema-registry', port=8081): Max retries exceeded with url: /subjects/batch-topic-value/versions?normalize=False (Caused by NewConnectionError('<urllib3.connection.HTTPConnection object at 0x7fae967ec620>: Failed to establish a new connection: [Errno 111] Connection refused'))"}
[2024-12-06T16:04:28.581+0000] {csv_to_kafka_with_redis.py:84} INFO - Row data before serialization: {'id': 'afd4bd8b-64bb-44d9-8015-20020ecf7a79', 'invoice_id': '300-71-4605', 'branch': 'C', 'city': 'Naypyitaw', 'customer_type': 'Member', 'gender': 'Male', 'product_line': 'Electronic accessories', 'unit_price': 86.04, 'quantity': 5, 'tax_5_percent': 21.51, 'total': 451.71, 'date': '2/25/2019', 'time': '11:24', 'payment': 'Ewallet', 'cogs': 430.2, 'gross_margin_percentage': 4.761904762, 'gross_income': 21.51, 'rating': 4.8}
[2024-12-06T16:04:28.586+0000] {csv_to_kafka_with_redis.py:90} ERROR - Error producing message: KafkaError{code=_VALUE_SERIALIZATION,val=-161,str="HTTPConnectionPool(host='schema-registry', port=8081): Max retries exceeded with url: /subjects/batch-topic-value/versions?normalize=False (Caused by NewConnectionError('<urllib3.connection.HTTPConnection object at 0x7fae967ecce0>: Failed to establish a new connection: [Errno 111] Connection refused'))"}
[2024-12-06T16:04:28.588+0000] {csv_to_kafka_with_redis.py:84} INFO - Row data before serialization: {'id': 'd67f59f8-ea1e-4086-a66a-adc0bf8a735c', 'invoice_id': '371-85-5789', 'branch': 'B', 'city': 'Mandalay', 'customer_type': 'Normal', 'gender': 'Male', 'product_line': 'Health and beauty', 'unit_price': 87.98, 'quantity': 3, 'tax_5_percent': 13.197, 'total': 277.137, 'date': '3/5/2019', 'time': '10:40', 'payment': 'Ewallet', 'cogs': 263.94, 'gross_margin_percentage': 4.761904762, 'gross_income': 13.197, 'rating': 5.1}
[2024-12-06T16:04:28.593+0000] {csv_to_kafka_with_redis.py:90} ERROR - Error producing message: KafkaError{code=_VALUE_SERIALIZATION,val=-161,str="HTTPConnectionPool(host='schema-registry', port=8081): Max retries exceeded with url: /subjects/batch-topic-value/versions?normalize=False (Caused by NewConnectionError('<urllib3.connection.HTTPConnection object at 0x7fae967ed340>: Failed to establish a new connection: [Errno 111] Connection refused'))"}
[2024-12-06T16:04:28.595+0000] {csv_to_kafka_with_redis.py:84} INFO - Row data before serialization: {'id': '6e8db34a-7382-4236-933c-7391d7117ceb', 'invoice_id': '273-16-6619', 'branch': 'B', 'city': 'Mandalay', 'customer_type': 'Normal', 'gender': 'Male', 'product_line': 'Home and lifestyle', 'unit_price': 33.2, 'quantity': 2, 'tax_5_percent': 3.32, 'total': 69.72, 'date': '3/15/2019', 'time': '12:20', 'payment': 'Credit card', 'cogs': 66.4, 'gross_margin_percentage': 4.761904762, 'gross_income': 3.32, 'rating': 4.4}
[2024-12-06T16:04:28.599+0000] {csv_to_kafka_with_redis.py:90} ERROR - Error producing message: KafkaError{code=_VALUE_SERIALIZATION,val=-161,str="HTTPConnectionPool(host='schema-registry', port=8081): Max retries exceeded with url: /subjects/batch-topic-value/versions?normalize=False (Caused by NewConnectionError('<urllib3.connection.HTTPConnection object at 0x7fae967ed880>: Failed to establish a new connection: [Errno 111] Connection refused'))"}
[2024-12-06T16:04:28.601+0000] {csv_to_kafka_with_redis.py:84} INFO - Row data before serialization: {'id': 'd13d0180-7044-4099-97fc-f3b417828130', 'invoice_id': '636-48-8204', 'branch': 'A', 'city': 'Yangon', 'customer_type': 'Normal', 'gender': 'Male', 'product_line': 'Electronic accessories', 'unit_price': 34.56, 'quantity': 5, 'tax_5_percent': 8.64, 'total': 181.44, 'date': '2/17/2019', 'time': '11:15', 'payment': 'Ewallet', 'cogs': 172.8, 'gross_margin_percentage': 4.761904762, 'gross_income': 8.64, 'rating': 9.9}
[2024-12-06T16:04:28.605+0000] {csv_to_kafka_with_redis.py:90} ERROR - Error producing message: KafkaError{code=_VALUE_SERIALIZATION,val=-161,str="HTTPConnectionPool(host='schema-registry', port=8081): Max retries exceeded with url: /subjects/batch-topic-value/versions?normalize=False (Caused by NewConnectionError('<urllib3.connection.HTTPConnection object at 0x7fae967b61e0>: Failed to establish a new connection: [Errno 111] Connection refused'))"}
[2024-12-06T16:04:28.606+0000] {csv_to_kafka_with_redis.py:84} INFO - Row data before serialization: {'id': 'a6982e98-68dc-4495-9d8c-9fbfb97210ef', 'invoice_id': '549-59-1358', 'branch': 'A', 'city': 'Yangon', 'customer_type': 'Member', 'gender': 'Male', 'product_line': 'Sports and travel', 'unit_price': 88.63, 'quantity': 3, 'tax_5_percent': 13.2945, 'total': 279.1845, 'date': '3/2/2019', 'time': '17:36', 'payment': 'Ewallet', 'cogs': 265.89, 'gross_margin_percentage': 4.761904762, 'gross_income': 13.2945, 'rating': 6.0}
[2024-12-06T16:04:28.611+0000] {csv_to_kafka_with_redis.py:90} ERROR - Error producing message: KafkaError{code=_VALUE_SERIALIZATION,val=-161,str="HTTPConnectionPool(host='schema-registry', port=8081): Max retries exceeded with url: /subjects/batch-topic-value/versions?normalize=False (Caused by NewConnectionError('<urllib3.connection.HTTPConnection object at 0x7fae967b6c30>: Failed to establish a new connection: [Errno 111] Connection refused'))"}
[2024-12-06T16:04:28.613+0000] {csv_to_kafka_with_redis.py:84} INFO - Row data before serialization: {'id': 'd2bdd60c-8693-4bbd-8b75-69650ab69b52', 'invoice_id': '227-03-5010', 'branch': 'A', 'city': 'Yangon', 'customer_type': 'Member', 'gender': 'Female', 'product_line': 'Home and lifestyle', 'unit_price': 52.59, 'quantity': 8, 'tax_5_percent': 21.036, 'total': 441.756, 'date': '3/22/2019', 'time': '19:20', 'payment': 'Credit card', 'cogs': 420.72, 'gross_margin_percentage': 4.761904762, 'gross_income': 21.036, 'rating': 8.5}
[2024-12-06T16:04:28.621+0000] {csv_to_kafka_with_redis.py:90} ERROR - Error producing message: KafkaError{code=_VALUE_SERIALIZATION,val=-161,str="HTTPConnectionPool(host='schema-registry', port=8081): Max retries exceeded with url: /subjects/batch-topic-value/versions?normalize=False (Caused by NewConnectionError('<urllib3.connection.HTTPConnection object at 0x7fae96789970>: Failed to establish a new connection: [Errno 111] Connection refused'))"}
[2024-12-06T16:04:28.623+0000] {csv_to_kafka_with_redis.py:84} INFO - Row data before serialization: {'id': '86d20838-2b2e-42d5-bfea-b3f63dd97cbc', 'invoice_id': '649-29-6775', 'branch': 'B', 'city': 'Mandalay', 'customer_type': 'Normal', 'gender': 'Male', 'product_line': 'Fashion accessories', 'unit_price': 33.52, 'quantity': 1, 'tax_5_percent': 1.676, 'total': 35.196, 'date': '2/8/2019', 'time': '15:31', 'payment': 'Cash', 'cogs': 33.52, 'gross_margin_percentage': 4.761904762, 'gross_income': 1.676, 'rating': 6.7}
[2024-12-06T16:04:28.628+0000] {csv_to_kafka_with_redis.py:90} ERROR - Error producing message: KafkaError{code=_VALUE_SERIALIZATION,val=-161,str="HTTPConnectionPool(host='schema-registry', port=8081): Max retries exceeded with url: /subjects/batch-topic-value/versions?normalize=False (Caused by NewConnectionError('<urllib3.connection.HTTPConnection object at 0x7fae9675f5f0>: Failed to establish a new connection: [Errno 111] Connection refused'))"}
[2024-12-06T16:04:28.630+0000] {csv_to_kafka_with_redis.py:84} INFO - Row data before serialization: {'id': 'a033b87b-608c-46ae-80f8-8aca9477b397', 'invoice_id': '189-17-4241', 'branch': 'A', 'city': 'Yangon', 'customer_type': 'Normal', 'gender': 'Female', 'product_line': 'Fashion accessories', 'unit_price': 87.67, 'quantity': 2, 'tax_5_percent': 8.767, 'total': 184.107, 'date': '3/10/2019', 'time': '12:17', 'payment': 'Credit card', 'cogs': 175.34, 'gross_margin_percentage': 4.761904762, 'gross_income': 8.767, 'rating': 7.7}
[2024-12-06T16:04:28.635+0000] {csv_to_kafka_with_redis.py:90} ERROR - Error producing message: KafkaError{code=_VALUE_SERIALIZATION,val=-161,str="HTTPConnectionPool(host='schema-registry', port=8081): Max retries exceeded with url: /subjects/batch-topic-value/versions?normalize=False (Caused by NewConnectionError('<urllib3.connection.HTTPConnection object at 0x7fae967ed580>: Failed to establish a new connection: [Errno 111] Connection refused'))"}
[2024-12-06T16:04:28.637+0000] {csv_to_kafka_with_redis.py:84} INFO - Row data before serialization: {'id': 'efa87b95-1184-4961-a135-0f4e35f57ba5', 'invoice_id': '145-94-9061', 'branch': 'B', 'city': 'Mandalay', 'customer_type': 'Normal', 'gender': 'Female', 'product_line': 'Food and beverages', 'unit_price': 88.36, 'quantity': 5, 'tax_5_percent': 22.09, 'total': 463.89, 'date': '1/25/2019', 'time': '19:48', 'payment': 'Cash', 'cogs': 441.8, 'gross_margin_percentage': 4.761904762, 'gross_income': 22.09, 'rating': 9.6}
[2024-12-06T16:04:28.641+0000] {csv_to_kafka_with_redis.py:90} ERROR - Error producing message: KafkaError{code=_VALUE_SERIALIZATION,val=-161,str="HTTPConnectionPool(host='schema-registry', port=8081): Max retries exceeded with url: /subjects/batch-topic-value/versions?normalize=False (Caused by NewConnectionError('<urllib3.connection.HTTPConnection object at 0x7fae967ecb30>: Failed to establish a new connection: [Errno 111] Connection refused'))"}
[2024-12-06T16:04:28.643+0000] {csv_to_kafka_with_redis.py:84} INFO - Row data before serialization: {'id': '594087aa-ebde-4ea6-886e-e6065de5c50b', 'invoice_id': '848-62-7243', 'branch': 'A', 'city': 'Yangon', 'customer_type': 'Normal', 'gender': 'Male', 'product_line': 'Health and beauty', 'unit_price': 24.89, 'quantity': 9, 'tax_5_percent': 11.2005, 'total': 235.2105, 'date': '3/15/2019', 'time': '15:36', 'payment': 'Cash', 'cogs': 224.01, 'gross_margin_percentage': 4.761904762, 'gross_income': 11.2005, 'rating': 7.4}
[2024-12-06T16:04:28.647+0000] {csv_to_kafka_with_redis.py:90} ERROR - Error producing message: KafkaError{code=_VALUE_SERIALIZATION,val=-161,str="HTTPConnectionPool(host='schema-registry', port=8081): Max retries exceeded with url: /subjects/batch-topic-value/versions?normalize=False (Caused by NewConnectionError('<urllib3.connection.HTTPConnection object at 0x7fae967ec4a0>: Failed to establish a new connection: [Errno 111] Connection refused'))"}
[2024-12-06T16:04:28.649+0000] {csv_to_kafka_with_redis.py:84} INFO - Row data before serialization: {'id': 'aaa9a050-ff57-434a-966d-1bcb6d53ba75', 'invoice_id': '871-79-8483', 'branch': 'B', 'city': 'Mandalay', 'customer_type': 'Normal', 'gender': 'Male', 'product_line': 'Fashion accessories', 'unit_price': 94.13, 'quantity': 5, 'tax_5_percent': 23.5325, 'total': 494.1825, 'date': '2/25/2019', 'time': '19:39', 'payment': 'Credit card', 'cogs': 470.65, 'gross_margin_percentage': 4.761904762, 'gross_income': 23.5325, 'rating': 4.8}
[2024-12-06T16:04:28.654+0000] {csv_to_kafka_with_redis.py:90} ERROR - Error producing message: KafkaError{code=_VALUE_SERIALIZATION,val=-161,str="HTTPConnectionPool(host='schema-registry', port=8081): Max retries exceeded with url: /subjects/batch-topic-value/versions?normalize=False (Caused by NewConnectionError('<urllib3.connection.HTTPConnection object at 0x7fae967edcd0>: Failed to establish a new connection: [Errno 111] Connection refused'))"}
[2024-12-06T16:04:28.655+0000] {csv_to_kafka_with_redis.py:84} INFO - Row data before serialization: {'id': 'f1f5a6a0-a240-488b-9637-1116e16602d9', 'invoice_id': '149-71-6266', 'branch': 'B', 'city': 'Mandalay', 'customer_type': 'Member', 'gender': 'Male', 'product_line': 'Sports and travel', 'unit_price': 78.07, 'quantity': 9, 'tax_5_percent': 35.1315, 'total': 737.7615, 'date': '1/28/2019', 'time': '12:43', 'payment': 'Cash', 'cogs': 702.63, 'gross_margin_percentage': 4.761904762, 'gross_income': 35.1315, 'rating': 4.5}
[2024-12-06T16:04:28.660+0000] {csv_to_kafka_with_redis.py:90} ERROR - Error producing message: KafkaError{code=_VALUE_SERIALIZATION,val=-161,str="HTTPConnectionPool(host='schema-registry', port=8081): Max retries exceeded with url: /subjects/batch-topic-value/versions?normalize=False (Caused by NewConnectionError('<urllib3.connection.HTTPConnection object at 0x7fae967ee1e0>: Failed to establish a new connection: [Errno 111] Connection refused'))"}
[2024-12-06T16:04:28.662+0000] {csv_to_kafka_with_redis.py:84} INFO - Row data before serialization: {'id': '18ec0d11-a810-4b17-a52e-e58113544df6', 'invoice_id': '640-49-2076', 'branch': 'B', 'city': 'Mandalay', 'customer_type': 'Normal', 'gender': 'Male', 'product_line': 'Sports and travel', 'unit_price': 83.78, 'quantity': 8, 'tax_5_percent': 33.512, 'total': 703.752, 'date': '1/10/2019', 'time': '14:49', 'payment': 'Cash', 'cogs': 670.24, 'gross_margin_percentage': 4.761904762, 'gross_income': 33.512, 'rating': 5.1}
[2024-12-06T16:04:28.666+0000] {csv_to_kafka_with_redis.py:90} ERROR - Error producing message: KafkaError{code=_VALUE_SERIALIZATION,val=-161,str="HTTPConnectionPool(host='schema-registry', port=8081): Max retries exceeded with url: /subjects/batch-topic-value/versions?normalize=False (Caused by NewConnectionError('<urllib3.connection.HTTPConnection object at 0x7fae967ee6f0>: Failed to establish a new connection: [Errno 111] Connection refused'))"}
[2024-12-06T16:04:28.668+0000] {csv_to_kafka_with_redis.py:84} INFO - Row data before serialization: {'id': 'de0de15e-b723-4bb0-8097-720132c36735', 'invoice_id': '595-11-5460', 'branch': 'A', 'city': 'Yangon', 'customer_type': 'Normal', 'gender': 'Male', 'product_line': 'Health and beauty', 'unit_price': 96.58, 'quantity': 2, 'tax_5_percent': 9.658, 'total': 202.818, 'date': '3/15/2019', 'time': '10:12', 'payment': 'Credit card', 'cogs': 193.16, 'gross_margin_percentage': 4.761904762, 'gross_income': 9.658, 'rating': 5.1}
[2024-12-06T16:04:28.672+0000] {csv_to_kafka_with_redis.py:90} ERROR - Error producing message: KafkaError{code=_VALUE_SERIALIZATION,val=-161,str="HTTPConnectionPool(host='schema-registry', port=8081): Max retries exceeded with url: /subjects/batch-topic-value/versions?normalize=False (Caused by NewConnectionError('<urllib3.connection.HTTPConnection object at 0x7fae967eeba0>: Failed to establish a new connection: [Errno 111] Connection refused'))"}
[2024-12-06T16:04:28.684+0000] {csv_to_kafka_with_redis.py:84} INFO - Row data before serialization: {'id': 'ee1ca4e6-7d06-4ccc-a69c-5e9c55d94d42', 'invoice_id': '183-56-6882', 'branch': 'C', 'city': 'Naypyitaw', 'customer_type': 'Member', 'gender': 'Female', 'product_line': 'Food and beverages', 'unit_price': 99.42, 'quantity': 4, 'tax_5_percent': 19.884, 'total': 417.564, 'date': '2/6/2019', 'time': '10:42', 'payment': 'Ewallet', 'cogs': 397.68, 'gross_margin_percentage': 4.761904762, 'gross_income': 19.884, 'rating': 7.5}
[2024-12-06T16:04:28.688+0000] {csv_to_kafka_with_redis.py:90} ERROR - Error producing message: KafkaError{code=_VALUE_SERIALIZATION,val=-161,str="HTTPConnectionPool(host='schema-registry', port=8081): Max retries exceeded with url: /subjects/batch-topic-value/versions?normalize=False (Caused by NewConnectionError('<urllib3.connection.HTTPConnection object at 0x7fae6e367530>: Failed to establish a new connection: [Errno 111] Connection refused'))"}
[2024-12-06T16:04:28.691+0000] {csv_to_kafka_with_redis.py:84} INFO - Row data before serialization: {'id': '472a9ea4-6842-47dd-8260-e11639732a52', 'invoice_id': '232-16-2483', 'branch': 'C', 'city': 'Naypyitaw', 'customer_type': 'Member', 'gender': 'Female', 'product_line': 'Sports and travel', 'unit_price': 68.12, 'quantity': 1, 'tax_5_percent': 3.406, 'total': 71.526, 'date': '1/7/2019', 'time': '12:28', 'payment': 'Ewallet', 'cogs': 68.12, 'gross_margin_percentage': 4.761904762, 'gross_income': 3.406, 'rating': 6.8}
[2024-12-06T16:04:28.696+0000] {csv_to_kafka_with_redis.py:90} ERROR - Error producing message: KafkaError{code=_VALUE_SERIALIZATION,val=-161,str="HTTPConnectionPool(host='schema-registry', port=8081): Max retries exceeded with url: /subjects/batch-topic-value/versions?normalize=False (Caused by NewConnectionError('<urllib3.connection.HTTPConnection object at 0x7fae967b7020>: Failed to establish a new connection: [Errno 111] Connection refused'))"}
[2024-12-06T16:04:28.698+0000] {csv_to_kafka_with_redis.py:84} INFO - Row data before serialization: {'id': 'd9ea37a8-5dc9-40a8-b314-30458074ce23', 'invoice_id': '129-29-8530', 'branch': 'A', 'city': 'Yangon', 'customer_type': 'Member', 'gender': 'Male', 'product_line': 'Sports and travel', 'unit_price': 62.62, 'quantity': 5, 'tax_5_percent': 15.655, 'total': 328.755, 'date': '3/10/2019', 'time': '19:15', 'payment': 'Ewallet', 'cogs': 313.1, 'gross_margin_percentage': 4.761904762, 'gross_income': 15.655, 'rating': 7.0}
[2024-12-06T16:04:28.703+0000] {csv_to_kafka_with_redis.py:90} ERROR - Error producing message: KafkaError{code=_VALUE_SERIALIZATION,val=-161,str="HTTPConnectionPool(host='schema-registry', port=8081): Max retries exceeded with url: /subjects/batch-topic-value/versions?normalize=False (Caused by NewConnectionError('<urllib3.connection.HTTPConnection object at 0x7fae967b5910>: Failed to establish a new connection: [Errno 111] Connection refused'))"}
[2024-12-06T16:04:28.705+0000] {csv_to_kafka_with_redis.py:84} INFO - Row data before serialization: {'id': '86e55588-48c4-4883-9e9d-545a03ba044b', 'invoice_id': '272-65-1806', 'branch': 'A', 'city': 'Yangon', 'customer_type': 'Normal', 'gender': 'Female', 'product_line': 'Electronic accessories', 'unit_price': 60.88, 'quantity': 9, 'tax_5_percent': 27.396, 'total': 575.316, 'date': '1/15/2019', 'time': '17:17', 'payment': 'Ewallet', 'cogs': 547.92, 'gross_margin_percentage': 4.761904762, 'gross_income': 27.396, 'rating': 4.7}
[2024-12-06T16:04:28.709+0000] {csv_to_kafka_with_redis.py:90} ERROR - Error producing message: KafkaError{code=_VALUE_SERIALIZATION,val=-161,str="HTTPConnectionPool(host='schema-registry', port=8081): Max retries exceeded with url: /subjects/batch-topic-value/versions?normalize=False (Caused by NewConnectionError('<urllib3.connection.HTTPConnection object at 0x7fae967b6420>: Failed to establish a new connection: [Errno 111] Connection refused'))"}
[2024-12-06T16:04:28.711+0000] {csv_to_kafka_with_redis.py:84} INFO - Row data before serialization: {'id': '68335eaa-8ea7-4c87-b72d-235eb27f93d5', 'invoice_id': '333-73-7901', 'branch': 'C', 'city': 'Naypyitaw', 'customer_type': 'Normal', 'gender': 'Female', 'product_line': 'Health and beauty', 'unit_price': 54.92, 'quantity': 8, 'tax_5_percent': 21.968, 'total': 461.328, 'date': '3/23/2019', 'time': '13:24', 'payment': 'Ewallet', 'cogs': 439.36, 'gross_margin_percentage': 4.761904762, 'gross_income': 21.968, 'rating': 7.6}
[2024-12-06T16:04:28.716+0000] {csv_to_kafka_with_redis.py:90} ERROR - Error producing message: KafkaError{code=_VALUE_SERIALIZATION,val=-161,str="HTTPConnectionPool(host='schema-registry', port=8081): Max retries exceeded with url: /subjects/batch-topic-value/versions?normalize=False (Caused by NewConnectionError('<urllib3.connection.HTTPConnection object at 0x7fae967ec050>: Failed to establish a new connection: [Errno 111] Connection refused'))"}
[2024-12-06T16:04:28.718+0000] {csv_to_kafka_with_redis.py:84} INFO - Row data before serialization: {'id': '131a1059-a292-4a33-b0f5-2fa1af8bbb7a', 'invoice_id': '777-82-7220', 'branch': 'B', 'city': 'Mandalay', 'customer_type': 'Member', 'gender': 'Male', 'product_line': 'Home and lifestyle', 'unit_price': 30.12, 'quantity': 8, 'tax_5_percent': 12.048, 'total': 253.008, 'date': '3/3/2019', 'time': '13:01', 'payment': 'Cash', 'cogs': 240.96, 'gross_margin_percentage': 4.761904762, 'gross_income': 12.048, 'rating': 7.7}
[2024-12-06T16:04:28.723+0000] {csv_to_kafka_with_redis.py:90} ERROR - Error producing message: KafkaError{code=_VALUE_SERIALIZATION,val=-161,str="HTTPConnectionPool(host='schema-registry', port=8081): Max retries exceeded with url: /subjects/batch-topic-value/versions?normalize=False (Caused by NewConnectionError('<urllib3.connection.HTTPConnection object at 0x7fae967ec590>: Failed to establish a new connection: [Errno 111] Connection refused'))"}
[2024-12-06T16:04:28.725+0000] {csv_to_kafka_with_redis.py:84} INFO - Row data before serialization: {'id': 'bc661bf2-1f18-448e-b277-42ea13748d2b', 'invoice_id': '280-35-5823', 'branch': 'B', 'city': 'Mandalay', 'customer_type': 'Member', 'gender': 'Female', 'product_line': 'Home and lifestyle', 'unit_price': 86.72, 'quantity': 1, 'tax_5_percent': 4.336, 'total': 91.056, 'date': '1/17/2019', 'time': '18:45', 'payment': 'Ewallet', 'cogs': 86.72, 'gross_margin_percentage': 4.761904762, 'gross_income': 4.336, 'rating': 7.9}
[2024-12-06T16:04:28.731+0000] {csv_to_kafka_with_redis.py:90} ERROR - Error producing message: KafkaError{code=_VALUE_SERIALIZATION,val=-161,str="HTTPConnectionPool(host='schema-registry', port=8081): Max retries exceeded with url: /subjects/batch-topic-value/versions?normalize=False (Caused by NewConnectionError('<urllib3.connection.HTTPConnection object at 0x7fae967ede80>: Failed to establish a new connection: [Errno 111] Connection refused'))"}
[2024-12-06T16:04:28.733+0000] {csv_to_kafka_with_redis.py:84} INFO - Row data before serialization: {'id': '1c42f876-8057-4426-817d-1b32f7283a58', 'invoice_id': '554-53-8700', 'branch': 'C', 'city': 'Naypyitaw', 'customer_type': 'Member', 'gender': 'Male', 'product_line': 'Home and lifestyle', 'unit_price': 56.11, 'quantity': 2, 'tax_5_percent': 5.611, 'total': 117.831, 'date': '2/2/2019', 'time': '10:11', 'payment': 'Cash', 'cogs': 112.22, 'gross_margin_percentage': 4.761904762, 'gross_income': 5.611, 'rating': 6.3}
[2024-12-06T16:04:28.737+0000] {csv_to_kafka_with_redis.py:90} ERROR - Error producing message: KafkaError{code=_VALUE_SERIALIZATION,val=-161,str="HTTPConnectionPool(host='schema-registry', port=8081): Max retries exceeded with url: /subjects/batch-topic-value/versions?normalize=False (Caused by NewConnectionError('<urllib3.connection.HTTPConnection object at 0x7fae967ed190>: Failed to establish a new connection: [Errno 111] Connection refused'))"}
[2024-12-06T16:04:28.739+0000] {csv_to_kafka_with_redis.py:84} INFO - Row data before serialization: {'id': 'aaa80775-c00f-4b1e-9800-04a5156d978d', 'invoice_id': '354-25-5821', 'branch': 'B', 'city': 'Mandalay', 'customer_type': 'Member', 'gender': 'Female', 'product_line': 'Sports and travel', 'unit_price': 69.12, 'quantity': 6, 'tax_5_percent': 20.736, 'total': 435.456, 'date': '2/8/2019', 'time': '13:03', 'payment': 'Cash', 'cogs': 414.72, 'gross_margin_percentage': 4.761904762, 'gross_income': 20.736, 'rating': 5.6}
[2024-12-06T16:04:28.745+0000] {csv_to_kafka_with_redis.py:90} ERROR - Error producing message: KafkaError{code=_VALUE_SERIALIZATION,val=-161,str="HTTPConnectionPool(host='schema-registry', port=8081): Max retries exceeded with url: /subjects/batch-topic-value/versions?normalize=False (Caused by NewConnectionError('<urllib3.connection.HTTPConnection object at 0x7fae967ed370>: Failed to establish a new connection: [Errno 111] Connection refused'))"}
[2024-12-06T16:04:28.747+0000] {csv_to_kafka_with_redis.py:84} INFO - Row data before serialization: {'id': '22097d18-fd58-4d2c-98e0-e00b9bb6ce4b', 'invoice_id': '228-96-1411', 'branch': 'C', 'city': 'Naypyitaw', 'customer_type': 'Member', 'gender': 'Female', 'product_line': 'Food and beverages', 'unit_price': 98.7, 'quantity': 8, 'tax_5_percent': 39.48, 'total': 829.08, 'date': '3/4/2019', 'time': '20:39', 'payment': 'Cash', 'cogs': 789.6, 'gross_margin_percentage': 4.761904762, 'gross_income': 39.48, 'rating': 7.6}
[2024-12-06T16:04:28.751+0000] {csv_to_kafka_with_redis.py:90} ERROR - Error producing message: KafkaError{code=_VALUE_SERIALIZATION,val=-161,str="HTTPConnectionPool(host='schema-registry', port=8081): Max retries exceeded with url: /subjects/batch-topic-value/versions?normalize=False (Caused by NewConnectionError('<urllib3.connection.HTTPConnection object at 0x7fae967ef080>: Failed to establish a new connection: [Errno 111] Connection refused'))"}
[2024-12-06T16:04:28.754+0000] {csv_to_kafka_with_redis.py:84} INFO - Row data before serialization: {'id': '45ec6b1f-2826-48ff-9b66-bd8a19c0cb3d', 'invoice_id': '617-15-4209', 'branch': 'C', 'city': 'Naypyitaw', 'customer_type': 'Member', 'gender': 'Male', 'product_line': 'Health and beauty', 'unit_price': 15.37, 'quantity': 2, 'tax_5_percent': 1.537, 'total': 32.277, 'date': '3/16/2019', 'time': '19:47', 'payment': 'Cash', 'cogs': 30.74, 'gross_margin_percentage': 4.761904762, 'gross_income': 1.537, 'rating': 7.2}
[2024-12-06T16:04:28.758+0000] {csv_to_kafka_with_redis.py:90} ERROR - Error producing message: KafkaError{code=_VALUE_SERIALIZATION,val=-161,str="HTTPConnectionPool(host='schema-registry', port=8081): Max retries exceeded with url: /subjects/batch-topic-value/versions?normalize=False (Caused by NewConnectionError('<urllib3.connection.HTTPConnection object at 0x7fae967ef500>: Failed to establish a new connection: [Errno 111] Connection refused'))"}
[2024-12-06T16:04:28.760+0000] {csv_to_kafka_with_redis.py:84} INFO - Row data before serialization: {'id': '90c7a706-5fbe-4a4f-baf1-ce981b4a2870', 'invoice_id': '132-32-9879', 'branch': 'B', 'city': 'Mandalay', 'customer_type': 'Member', 'gender': 'Female', 'product_line': 'Electronic accessories', 'unit_price': 93.96, 'quantity': 4, 'tax_5_percent': 18.792, 'total': 394.632, 'date': '3/9/2019', 'time': '18:00', 'payment': 'Cash', 'cogs': 375.84, 'gross_margin_percentage': 4.761904762, 'gross_income': 18.792, 'rating': 9.5}
[2024-12-06T16:04:28.766+0000] {csv_to_kafka_with_redis.py:90} ERROR - Error producing message: KafkaError{code=_VALUE_SERIALIZATION,val=-161,str="HTTPConnectionPool(host='schema-registry', port=8081): Max retries exceeded with url: /subjects/batch-topic-value/versions?normalize=False (Caused by NewConnectionError('<urllib3.connection.HTTPConnection object at 0x7fae967b69c0>: Failed to establish a new connection: [Errno 111] Connection refused'))"}
[2024-12-06T16:04:28.768+0000] {csv_to_kafka_with_redis.py:84} INFO - Row data before serialization: {'id': '1cc89bdd-f7d4-4f75-8413-9d73b7a3f9a9', 'invoice_id': '370-41-7321', 'branch': 'B', 'city': 'Mandalay', 'customer_type': 'Member', 'gender': 'Male', 'product_line': 'Health and beauty', 'unit_price': 56.69, 'quantity': 9, 'tax_5_percent': 25.5105, 'total': 535.7205, 'date': '2/27/2019', 'time': '17:24', 'payment': 'Credit card', 'cogs': 510.21, 'gross_margin_percentage': 4.761904762, 'gross_income': 25.5105, 'rating': 8.4}
[2024-12-06T16:04:28.772+0000] {csv_to_kafka_with_redis.py:90} ERROR - Error producing message: KafkaError{code=_VALUE_SERIALIZATION,val=-161,str="HTTPConnectionPool(host='schema-registry', port=8081): Max retries exceeded with url: /subjects/batch-topic-value/versions?normalize=False (Caused by NewConnectionError('<urllib3.connection.HTTPConnection object at 0x7fae96788290>: Failed to establish a new connection: [Errno 111] Connection refused'))"}
[2024-12-06T16:04:28.774+0000] {csv_to_kafka_with_redis.py:84} INFO - Row data before serialization: {'id': 'e74aa30c-5953-45eb-a5ec-908ee479f26d', 'invoice_id': '727-46-3608', 'branch': 'B', 'city': 'Mandalay', 'customer_type': 'Member', 'gender': 'Female', 'product_line': 'Food and beverages', 'unit_price': 20.01, 'quantity': 9, 'tax_5_percent': 9.0045, 'total': 189.0945, 'date': '2/6/2019', 'time': '15:47', 'payment': 'Ewallet', 'cogs': 180.09, 'gross_margin_percentage': 4.761904762, 'gross_income': 9.0045, 'rating': 4.1}
[2024-12-06T16:04:28.778+0000] {csv_to_kafka_with_redis.py:90} ERROR - Error producing message: KafkaError{code=_VALUE_SERIALIZATION,val=-161,str="HTTPConnectionPool(host='schema-registry', port=8081): Max retries exceeded with url: /subjects/batch-topic-value/versions?normalize=False (Caused by NewConnectionError('<urllib3.connection.HTTPConnection object at 0x7fae9675f170>: Failed to establish a new connection: [Errno 111] Connection refused'))"}
[2024-12-06T16:04:28.780+0000] {csv_to_kafka_with_redis.py:84} INFO - Row data before serialization: {'id': '7b547632-61db-4332-ac1c-b59043a8cdcd', 'invoice_id': '669-54-1719', 'branch': 'B', 'city': 'Mandalay', 'customer_type': 'Member', 'gender': 'Male', 'product_line': 'Electronic accessories', 'unit_price': 18.93, 'quantity': 6, 'tax_5_percent': 5.679, 'total': 119.259, 'date': '2/10/2019', 'time': '12:45', 'payment': 'Credit card', 'cogs': 113.58, 'gross_margin_percentage': 4.761904762, 'gross_income': 5.679, 'rating': 8.1}
[2024-12-06T16:04:28.785+0000] {csv_to_kafka_with_redis.py:90} ERROR - Error producing message: KafkaError{code=_VALUE_SERIALIZATION,val=-161,str="HTTPConnectionPool(host='schema-registry', port=8081): Max retries exceeded with url: /subjects/batch-topic-value/versions?normalize=False (Caused by NewConnectionError('<urllib3.connection.HTTPConnection object at 0x7fae967ef1a0>: Failed to establish a new connection: [Errno 111] Connection refused'))"}
[2024-12-06T16:04:28.787+0000] {csv_to_kafka_with_redis.py:84} INFO - Row data before serialization: {'id': '932b52c6-12d1-4dd5-acba-a28292e93ba8', 'invoice_id': '574-22-5561', 'branch': 'C', 'city': 'Naypyitaw', 'customer_type': 'Member', 'gender': 'Female', 'product_line': 'Fashion accessories', 'unit_price': 82.63, 'quantity': 10, 'tax_5_percent': 41.315, 'total': 867.615, 'date': '3/19/2019', 'time': '17:08', 'payment': 'Ewallet', 'cogs': 826.3, 'gross_margin_percentage': 4.761904762, 'gross_income': 41.315, 'rating': 7.9}
[2024-12-06T16:04:28.792+0000] {csv_to_kafka_with_redis.py:90} ERROR - Error producing message: KafkaError{code=_VALUE_SERIALIZATION,val=-161,str="HTTPConnectionPool(host='schema-registry', port=8081): Max retries exceeded with url: /subjects/batch-topic-value/versions?normalize=False (Caused by NewConnectionError('<urllib3.connection.HTTPConnection object at 0x7fae967ef0b0>: Failed to establish a new connection: [Errno 111] Connection refused'))"}
[2024-12-06T16:04:28.793+0000] {csv_to_kafka_with_redis.py:94} INFO - Batch 1 envoyé à Kafka.
[2024-12-06T16:04:28.799+0000] {csv_to_kafka_with_redis.py:98} INFO - Redis batch status: READY
[2024-12-06T16:09:22.328+0000] {local_task_job_runner.py:346} WARNING - State of this instance has been externally set to failed. Terminating instance.
[2024-12-06T16:09:22.330+0000] {local_task_job_runner.py:245} INFO - ::endgroup::
[2024-12-06T16:09:22.332+0000] {process_utils.py:132} INFO - Sending 15 to group 96. PIDs of all processes in the group: [96]
[2024-12-06T16:09:22.333+0000] {process_utils.py:87} INFO - Sending the signal 15 to group 96
[2024-12-06T16:09:22.335+0000] {taskinstance.py:3093} ERROR - Received SIGTERM. Terminating subprocesses.
[2024-12-06T16:09:22.400+0000] {taskinstance.py:340} INFO - ::group::Post task execution logs
[2024-12-06T16:09:22.428+0000] {process_utils.py:80} INFO - Process psutil.Process(pid=96, status='terminated', exitcode=0, started='16:04:15') (96) terminated with exit code 0
