[2024-12-09T15:54:31.028+0000] {local_task_job_runner.py:123} INFO - ::group::Pre task execution logs
[2024-12-09T15:54:31.100+0000] {taskinstance.py:2613} INFO - Dependencies all met for dep_context=non-requeueable deps ti=<TaskInstance: dagappi.process_task_publish_dagappi manual__2024-12-09T15:54:24.839362+00:00 [queued]>
[2024-12-09T15:54:31.157+0000] {taskinstance.py:2613} INFO - Dependencies all met for dep_context=requeueable deps ti=<TaskInstance: dagappi.process_task_publish_dagappi manual__2024-12-09T15:54:24.839362+00:00 [queued]>
[2024-12-09T15:54:31.160+0000] {taskinstance.py:2866} INFO - Starting attempt 1 of 1
[2024-12-09T15:54:31.364+0000] {taskinstance.py:2889} INFO - Executing <Task(PythonOperator): process_task_publish_dagappi> on 2024-12-09 15:54:24.839362+00:00
[2024-12-09T15:54:31.415+0000] {logging_mixin.py:190} WARNING - /home/airflow/.local/lib/python3.12/site-packages/airflow/task/task_runner/standard_task_runner.py:70 DeprecationWarning: This process (pid=240) is multi-threaded, use of fork() may lead to deadlocks in the child.
[2024-12-09T15:54:31.404+0000] {standard_task_runner.py:104} INFO - Running: ['airflow', 'tasks', 'run', 'dagappi', 'process_task_publish_dagappi', 'manual__2024-12-09T15:54:24.839362+00:00', '--job-id', '250', '--raw', '--subdir', 'DAGS_FOLDER/dag_streaming.py', '--cfg-path', '/tmp/tmp_y6cmv60']
[2024-12-09T15:54:31.423+0000] {standard_task_runner.py:105} INFO - Job 250: Subtask process_task_publish_dagappi
[2024-12-09T15:54:31.418+0000] {standard_task_runner.py:72} INFO - Started process 254 to run task
[2024-12-09T15:54:31.815+0000] {task_command.py:467} INFO - Running <TaskInstance: dagappi.process_task_publish_dagappi manual__2024-12-09T15:54:24.839362+00:00 [running]> on host 45770b1a429e
[2024-12-09T15:54:32.006+0000] {taskinstance.py:3132} INFO - Exporting env vars: AIRFLOW_CTX_DAG_OWNER='admin' AIRFLOW_CTX_DAG_ID='dagappi' AIRFLOW_CTX_TASK_ID='process_task_publish_dagappi' AIRFLOW_CTX_EXECUTION_DATE='2024-12-09T15:54:24.839362+00:00' AIRFLOW_CTX_TRY_NUMBER='1' AIRFLOW_CTX_DAG_RUN_ID='manual__2024-12-09T15:54:24.839362+00:00'
[2024-12-09T15:54:32.009+0000] {taskinstance.py:731} INFO - ::endgroup::
[2024-12-09T15:56:17.830+0000] {job.py:229} INFO - Heartbeat recovered after 39.26 seconds
[2024-12-09T15:58:58.351+0000] {local_task_job_runner.py:346} WARNING - State of this instance has been externally set to queued. Terminating instance.
[2024-12-09T15:58:58.373+0000] {local_task_job_runner.py:245} INFO - ::endgroup::
[2024-12-09T15:58:58.383+0000] {process_utils.py:132} INFO - Sending 15 to group 254. PIDs of all processes in the group: [254]
[2024-12-09T15:58:58.385+0000] {process_utils.py:87} INFO - Sending the signal 15 to group 254
[2024-12-09T15:58:58.386+0000] {taskinstance.py:3093} ERROR - Received SIGTERM. Terminating subprocesses.
[2024-12-09T15:58:58.471+0000] {taskinstance.py:3311} ERROR - Task failed with exception
Traceback (most recent call last):
  File "/home/airflow/.local/lib/python3.12/site-packages/airflow/models/taskinstance.py", line 767, in _execute_task
    result = _execute_callable(context=context, **execute_callable_kwargs)
             ^^^^^^^^^^^^^^^^^^^^^^^^^^^^^^^^^^^^^^^^^^^^^^^^^^^^^^^^^^^^^
  File "/home/airflow/.local/lib/python3.12/site-packages/airflow/models/taskinstance.py", line 733, in _execute_callable
    return ExecutionCallableRunner(
           ^^^^^^^^^^^^^^^^^^^^^^^^
  File "/home/airflow/.local/lib/python3.12/site-packages/airflow/utils/operator_helpers.py", line 252, in run
    return self.func(*args, **kwargs)
           ^^^^^^^^^^^^^^^^^^^^^^^^^^
  File "/home/airflow/.local/lib/python3.12/site-packages/airflow/models/baseoperator.py", line 417, in wrapper
    return func(self, *args, **kwargs)
           ^^^^^^^^^^^^^^^^^^^^^^^^^^^
  File "/home/airflow/.local/lib/python3.12/site-packages/airflow/operators/python.py", line 238, in execute
    return_value = self.execute_callable()
                   ^^^^^^^^^^^^^^^^^^^^^^^
  File "/home/airflow/.local/lib/python3.12/site-packages/airflow/operators/python.py", line 256, in execute_callable
    return runner.run(*self.op_args, **self.op_kwargs)
           ^^^^^^^^^^^^^^^^^^^^^^^^^^^^^^^^^^^^^^^^^^^
  File "/home/airflow/.local/lib/python3.12/site-packages/airflow/utils/operator_helpers.py", line 252, in run
    return self.func(*args, **kwargs)
           ^^^^^^^^^^^^^^^^^^^^^^^^^^
  File "/opt/airflow/dags/dag_streaming.py", line 69, in process_sales_and_publish
    time.sleep(30)
  File "/home/airflow/.local/lib/python3.12/site-packages/airflow/models/taskinstance.py", line 3095, in signal_handler
    raise AirflowTaskTerminated("Task received SIGTERM signal")
airflow.exceptions.AirflowTaskTerminated: Task received SIGTERM signal
[2024-12-09T15:58:58.539+0000] {taskinstance.py:1225} INFO - Marking task as FAILED. dag_id=dagappi, task_id=process_task_publish_dagappi, run_id=manual__2024-12-09T15:54:24.839362+00:00, execution_date=20241209T155424, start_date=20241209T155431, end_date=20241209T155858
[2024-12-09T15:58:58.704+0000] {taskinstance.py:340} INFO - ::group::Post task execution logs
[2024-12-09T15:58:58.762+0000] {process_utils.py:80} INFO - Process psutil.Process(pid=254, status='terminated', exitcode=2, started='15:54:31') (254) terminated with exit code 2
